Workbook
Name Administrative: '📝 INPUT VALUES'!$B$45
Name Amortization: '📝 INPUT VALUES'!$B$53
Name City: '📝 INPUT VALUES'!$B$12
Name ClosingCosts: '📝 INPUT VALUES'!$B$24
Name Contingency: '📝 INPUT VALUES'!$B$27
Name ExitCapRate: '📝 INPUT VALUES'!$B$58
Name ExpenseGrowth: '📝 INPUT VALUES'!$B$57
Name FFE: '📝 INPUT VALUES'!$B$26
Name FinancingFees: '📝 INPUT VALUES'!$B$28
Name GrossRent: '📝 INPUT VALUES'!$B$34
Name HoldPeriod: '📝 INPUT VALUES'!$B$20
Name Insurance: '📝 INPUT VALUES'!$B$40
Name InterestRate: '📝 INPUT VALUES'!$B$51
Name Landscaping: '📝 INPUT VALUES'!$B$44
Name LoanAmount: '📝 INPUT VALUES'!$B$50
Name LoanTerm: '📝 INPUT VALUES'!$B$52
Name Marketing: '📝 INPUT VALUES'!$B$46
Name MarketingCosts: '📝 INPUT VALUES'!$B$30
Name MgmtPct: '📝 INPUT VALUES'!$B$41
Name Occupancy: '📝 INPUT VALUES'!$B$19
Name OtherAcqCosts: '📝 INPUT VALUES'!$B$31
Name OtherIncome: '📝 INPUT VALUES'!$B$35
Name OtherOpex: '📝 INPUT VALUES'!$B$47
Name PropName: '📝 INPUT VALUES'!$B$11
Name PropTaxes: '📝 INPUT VALUES'!$B$39
Name PropType: '📝 INPUT VALUES'!$B$15
Name PurchasePrice: '📝 INPUT VALUES'!$B$23
Name RenovationBudget: '📝 INPUT VALUES'!$B$25
Name RentGrowth: '📝 INPUT VALUES'!$B$56
Name Repairs: '📝 INPUT VALUES'!$B$42
Name SqFt: '📝 INPUT VALUES'!$B$17
Name State: '📝 INPUT VALUES'!$B$13
Name Units: '📝 INPUT VALUES'!$B$16
Name Utilities: '📝 INPUT VALUES'!$B$43
Name VacancyRate: '📝 INPUT VALUES'!$B$36
Name WorkingCapital: '📝 INPUT VALUES'!$B$29
Name Year10NOI: '4️⃣ 10-Year Projections'!$K$12
Name Year1CashFlow: '5️⃣ Financing & Returns'!$B$24
Name Year1EGI: '2️⃣ Year 1 Pro Forma'!$B$12
Name Year1NOI: '2️⃣ Year 1 Pro Forma'!$B$27
Name Year5NOI: '3️⃣ 5-Year Projections'!$F$12
Name YearBuilt: '📝 INPUT VALUES'!$B$18
Name ZipCode: '📝 INPUT VALUES'!$B$14

Sheet ⚠️ DISCLAIMER & LEGAL
A1: IMPORTANT LEGAL NOTICE - READ BEFORE USE
A4: COPYRIGHT NOTICE
A5: © 2024 DeFi Assets LLC. All Rights Reserved.
A7: This CapSeriesX Financial Calculator (the 'Calculator') is proprietary material owned by DeFi Assets LLC, a subsidiary of Apex DeFi Labs Inc. This Calculator and all associated documentation, templates, and materials are protected by United States and international copyright laws and treaties.
D8: DEFI ASSETS LLLC
A9: Unauthorized reproduction, distribution, modification, public display, or creation of derivative works from this Calculator is strictly prohibited and may result in severe civil and criminal penalties.
A12: CONFIDENTIAL AND PROPRIETARY INFORMATION
A13: This Calculator contains confidential and proprietary information belonging to DeFi Assets LLC and CapSeriesX. By accessing and using this Calculator, you acknowledge that:
A15: 1. CONFIDENTIALITY OBLIGATION: All information contained herein, including methodologies, formulas, assumptions, default values, and the structure of the Calculator itself, constitutes confidential and proprietary information ('Confidential Information').
A17: 2. NON-DISCLOSURE AGREEMENT: Use of this Calculator is subject to the Non-Disclosure Agreement (NDA) executed between you and DeFi Assets LLC. All terms and conditions of that NDA are incorporated herein by reference and remain in full force and effect.
A19: 3. PERMITTED USE: This Calculator may be used solely for the purpose of preparing property submission packages to CapSeriesX in accordance with your Partnership Agreement. Any other use is expressly prohibited.
A21: 4. NO REDISTRIBUTION: You may NOT share, distribute, or provide access to this Calculator to any third party without prior written consent from DeFi Assets LLC. This includes but is not limited to property owners, investors, brokers, or other partners.
A23: 5. PROTECTION MEASURES: This Calculator is password-protected. You must not share the password with unauthorized parties or attempt to circumvent the protection mechanisms.
A26: DISCLAIMER OF WARRANTIES
A27: THIS CALCULATOR IS PROVIDED 'AS IS' WITHOUT WARRANTY OF ANY KIND, EXPRESS OR IMPLIED, INCLUDING BUT NOT LIMITED TO THE WARRANTIES OF MERCHANTABILITY, FITNESS FOR A PARTICULAR PURPOSE, AND NON-INFRINGEMENT.
A29: DeFi Assets LLC makes no representations or warranties regarding:
A30: • The accuracy, completeness, or reliability of calculations
... A180: Last Updated: December 8, 2024

Sheet 📝 INPUT VALUES
A1: ALL INPUT VALUES - ENTER YOUR DATA HERE
A3: INSTRUCTIONS:
A4: 1. Enter all your property data in the YELLOW cells below
A5: 2. All other worksheets will automatically calculate
A6: 3. Do NOT edit cells in other sheets - they contain formulas
A7: 4. This sheet is the ONLY place you need to enter data
A9: PROPERTY BASIC INFORMATION
A10: Description | B10: Your Input | C10: Notes/Instructions
A11: Property Name/Address | B11: 123 Main Street | C11: Full property address
A12: City | B12: Austin
A13: State | B13: TX
A14: ZIP Code | B14: 78701
A15: Property Type | B15: Multi-Family | C15: Single-Family, Multi-Family, Commercial, etc.
A16: Number of Units | B16: 24 | C16: Total rentable units
A17: Total Square Footage | B17: 18000 | C17: Total building square footage
A18: Year Built | B18: 2005
A19: Current Occupancy % | B19: 95 | C19: Enter as number (e.g., 95 for 95%)
A20: Hold Period (Years) | B20: 5 | C20: Planned years to hold property
A22: ACQUISITION COSTS
A23: Purchase Price | B23: 5000000 | C23: Agreed purchase price
A24: Closing Costs | B24: 150000 | C24: Title, escrow, legal fees (2-3% typical)
A25: Renovation Budget | B25: 500000 | C25: All improvement costs
A26: FF&E (Furniture/Fixtures) | B26: 0 | C26: If applicable
A27: Contingency Reserve | B27: 50000 | C27: 5-10% of renovation budget
A28: Financing Fees | B28: 50000 | C28: Loan origination, points
A29: Working Capital Reserve | B29: 100000 | C29: Operating reserve
A30: Marketing/Lease-Up Costs | B30: 25000 | C30: If repositioning
A31: Other Acquisition Costs | B31: 0 | C31: Any other costs
A33: INCOME ASSUMPTIONS (YEAR 1)
A34: Gross Rental Income (Annual) | B34: 600000 | C34: Total annual rent from all units
A35: Other Income (Annual) | B35: 20000 | C35: Parking, laundry, pet fees, etc.
A36: Vacancy Rate % | B36: 5 | C36: Expected vacancy % (enter as 5 for 5%)
A38: OPERATING EXPENSES (YEAR 1)
A39: Property Taxes (Annual) | B39: 60000 | C39: From county assessor
A40: Insurance (Annual) | B40: 18000 | C40: Property & liability
A41: Property Management % of EGI | B41: 5 | C41: Typically 4-10% (enter as 5 for 5%)
A42: Repairs & Maintenance (Annual) | B42: 30000 | C42: Ongoing repairs
A43: Utilities (Annual) | B43: 24000 | C43: If owner-paid
A44: Landscaping/Grounds (Annual) | B44: 12000
A45: Administrative (Annual) | B45: 8000 | C45: Office, supplies, etc.
...

Sheet 1️⃣ Acquisition
A1: ACQUISITION SUMMARY
A3: Uses of Funds
A4: Purchase Price | B4: =PurchasePrice -> 5000000
A5: Closing Costs | B5: =ClosingCosts -> 150000
A6: Renovation Budget | B6: =RenovationBudget -> 500000
A7: FF&E | B7: =FFE -> 0
A8: Contingency Reserve | B8: =Contingency -> 50000
A9: Financing Fees | B9: =FinancingFees -> 50000
A10: Working Capital | B10: =WorkingCapital -> 100000
A11: Marketing/Lease-Up | B11: =MarketingCosts -> 25000
A12: Other Costs | B12: =OtherAcqCosts -> 0
A14: TOTAL PROJECT COST | B14: =SUM(B4:B12) -> 5875000
A16: Per Unit Metrics
A17: Price Per Unit | B17: =B14/Units -> 244791.67
A18: Price Per Square Foot | B18: =B14/SqFt -> 326.38889

Sheet 2️⃣ Year 1 Pro Forma
A1: YEAR 1 OPERATING PRO FORMA
A3: INCOME
A4: Gross Rental Income | B4: =GrossRent -> 600000
A5: Other Income | B5: =OtherIncome -> 20000
A6: Gross Potential Income | B6: =B4+B5 -> 620000
A8: Less: Vacancy & Credit Loss
A9: Vacancy Rate % | B9: =VacancyRate/100 -> 0.05
A10: Vacancy Loss $ | B10: =B6*(VacancyRate/100) -> 31000
A12: EFFECTIVE GROSS INCOME | B12: =B6-B10 -> 589000
A14: OPERATING EXPENSES
A15: Property Taxes | B15: =PropTaxes -> 60000
A16: Insurance | B16: =Insurance -> 18000
A17: Property Management | B17: =B12*(MgmtPct/100) -> 29450
A18: Repairs & Maintenance | B18: =Repairs -> 30000
A19: Utilities | B19: =Utilities -> 24000
A20: Landscaping/Grounds | B20: =Landscaping -> 12000
A21: Administrative | B21: =Administrative -> 8000
A22: Marketing/Advertising | B22: =Marketing -> 6000
A23: Other Operating Expenses | B23: =OtherOpex -> 5000
A25: TOTAL OPERATING EXPENSES | B25: =SUM(B15:B23) -> 192450
A27: NET OPERATING INCOME (NOI) | B27: =B12-B25 -> 396550
A29: KEY METRICS
A30: Operating Expense Ratio | B30: =IF(B12>0,B25/B12,0) -> 0.32674024
A31: NOI Margin % | B31: =IF(B12>0,B27/B12,0) -> 0.67325976
A32: Income Per Unit | B32: =IF(Units>0,B12/Units,0) -> 24541.667
A33: Expense Per Unit | B33: =IF(Units>0,B25/Units,0) -> 8018.75
A34: NOI Per Unit | B34: =IF(Units>0,B27/Units,0) -> 16522.917

Sheet 3️⃣ 5-Year Projections
A1: 5-YEAR PRO FORMA PROJECTIONS
B3: Year 1 | C3: Year 2 | D3: Year 3 | E3: Year 4 | F3: Year 5
A4: Gross Rental Income | B4: =GrossRent -> 600000 | C4: =B4*(1+RentGrowth/100) -> 618000 | D4: =C4*(1+RentGrowth/100) -> 636540 | E4: =D4*(1+RentGrowth/100) -> 655636.2 | F4: =E4*(1+RentGrowth/100) -> 675305.29
A5: Other Income | B5: =OtherIncome -> 20000 | C5: =B5*(1+RentGrowth/100) -> 20600 | D5: =C5*(1+RentGrowth/100) -> 21218 | E5: =D5*(1+RentGrowth/100) -> 21854.54 | F5: =E5*(1+RentGrowth/100) -> 22510.176
A6: Gross Potential Income | B6: =B4+B5 -> 620000 | C6: =C4+C5 -> 638600 | D6: =D4+D5 -> 657758 | E6: =E4+E5 -> 677490.74 | F6: =F4+F5 -> 697815.46
A7: Vacancy Loss | B7: =B6*(VacancyRate/100) -> 31000 | C7: =C6*(VacancyRate/100) -> 31930 | D7: =D6*(VacancyRate/100) -> 32887.9 | E7: =E6*(VacancyRate/100) -> 33874.537 | F7: =F6*(VacancyRate/100) -> 34890.773
A8: EFFECTIVE GROSS INCOME | B8: =B6-B7 -> 589000 | C8: =C6-C7 -> 606670 | D8: =D6-D7 -> 624870.1 | E8: =E6-E7 -> 643616.2 | F8: =F6-F7 -> 662924.69
A10: Total Operating Expenses | B10: ='2️⃣ Year 1 Pro Forma'!B25 -> 192450 | C10: =B10*(1+ExpenseGrowth/100) -> 197261.25 | D10: =C10*(1+ExpenseGrowth/100) -> 202192.78 | E10: =D10*(1+ExpenseGrowth/100) -> 207247.6 | F10: =E10*(1+ExpenseGrowth/100) -> 212428.79
A12: NET OPERATING INCOME | B12: =B8-B10 -> 396550 | C12: =C8-C10 -> 409408.75 | D12: =D8-D10 -> 422677.32 | E12: =E8-E10 -> 436368.6 | F12: =F8-F10 -> 450495.9

Sheet 4️⃣ 10-Year Projections
A1: 10-YEAR PRO FORMA PROJECTIONS
B3: Year 1 | C3: Year 2 | D3: Year 3 | E3: Year 4 | F3: Year 5 | G3: Year 6 | H3: Year 7 | I3: Year 8 | J3: Year 9 | K3: Year 10
A4: Gross Rental Income | B4: =GrossRent -> 600000 | C4: =B4*(1+RentGrowth/100) -> 618000 | D4: =C4*(1+RentGrowth/100) -> 636540 | E4: =D4*(1+RentGrowth/100) -> 655636.2 | F4: =E4*(1+RentGrowth/100) -> 675305.29 | G4: =F4*(1+RentGrowth/100) -> 695564.44 | H4: =G4*(1+RentGrowth/100) -> 716431.38 | I4: =H4*(1+RentGrowth/100) -> 737924.32 | J4: =I4*(1+RentGrowth/100) -> 760062.05 | K4: =J4*(1+RentGrowth/100) -> 782863.91
A5: Other Income | B5: =OtherIncome -> 20000 | C5: =B5*(1+RentGrowth/100) -> 20600 | D5: =C5*(1+RentGrowth/100) -> 21218 | E5: =D5*(1+RentGrowth/100) -> 21854.54 | F5: =E5*(1+RentGrowth/100) -> 22510.176 | G5: =F5*(1+RentGrowth/100) -> 23185.481 | H5: =G5*(1+RentGrowth/100) -> 23881.046 | I5: =H5*(1+RentGrowth/100) -> 24597.477 | J5: =I5*(1+RentGrowth/100) -> 25335.402 | K5: =J5*(1+RentGrowth/100) -> 26095.464
A6: Gross Potential Income | B6: =B4+B5 -> 620000 | C6: =C4+C5 -> 638600 | D6: =D4+D5 -> 657758 | E6: =E4+E5 -> 677490.74 | F6: =F4+F5 -> 697815.46 | G6: =G4+G5 -> 718749.93 | H6: =H4+H5 -> 740312.42 | I6: =I4+I5 -> 762521.8 | ... K6: =K4+K5 -> 808959.37
A7: Vacancy Loss | B7: =B6*(VacancyRate/100) -> 31000 | C7: =C6*(VacancyRate/100) -> 31930 | D7: =D6*(VacancyRate/100) -> 32887.9 | E7: =E6*(VacancyRate/100) -> 33874.537 | F7: =F6*(VacancyRate/100) -> 34890.773 | G7: =G6*(VacancyRate/100) -> 35937.496 | H7: =H6*(VacancyRate/100) -> 37015.621 | I7: =I6*(VacancyRate/100) -> 38126.09 | ... K7: =K6*(VacancyRate/100) -> 40447.969
A8: EFFECTIVE GROSS INCOME | B8: =B6-B7 -> 589000 | C8: =C6-C7 -> 606670 | D8: =D6-D7 -> 624870.1 | E8: =E6-E7 -> 643616.2 | F8: =F6-F7 -> 662924.69 | G8: =G6-G7 -> 682812.43 | H8: =H6-H7 -> 703296.8 | I8: =I6-I7 -> 724395.71 | ... K8: =K6-K7 -> 768511.41
A10: Total Operating Expenses | B10: ='2️⃣ Year 1 Pro Forma'!B25 -> 192450 | C10: =B10*(1+ExpenseGrowth/100) -> 197261.25 | D10: =C10*(1+ExpenseGrowth/100) -> 202192.78 | E10: =D10*(1+ExpenseGrowth/100) -> 207247.6 | F10: =E10*(1+ExpenseGrowth/100) -> 212428.79 | G10: =F10*(1+ExpenseGrowth/100) -> 217739.51 | H10: =G10*(1+ExpenseGrowth/100) -> 223183 | I10: =H10*(1+ExpenseGrowth/100) -> 228762.57 | J10: =I10*(1+ExpenseGrowth/100) -> 234481.64 | K10: =J10*(1+ExpenseGrowth/100) -> 240343.68
A12: NET OPERATING INCOME | B12: =B8-B10 -> 396550 | C12: =C8-C10 -> 409408.75 | D12: =D8-D10 -> 422677.32 | E12: =E8-E10 -> 436368.6 | F12: =F8-F10 -> 450495.9 | G12: =G8-G10 -> 465072.92 | H12: =H8-H10 -> 480113.8 | I12: =I8-I10 -> 495633.13 | ... K12: =K8-K10 -> 528167.73

Sheet 5️⃣ Financing & Returns
A1: FINANCING STRUCTURE & RETURN METRICS
A3: DEBT FINANCING
A4: Loan Amount | B4: =LoanAmount -> 3750000
A5: Interest Rate % | B5: =InterestRate/100 -> 0.065
A6: Loan Term (Years) | B6: =LoanTerm -> 10
A7: Amortization (Years) | B7: =Amortization -> 30
A8: Annual Debt Service | B8: =IF(AND(InterestRate>0,Amortization>0,LoanAmount>0),-PMT(InterestRate/100,Amortization,LoanAmount),0) -> 287165.41
A9: Monthly Payment | B9: =B8/12 -> 23930.451
A11: SOURCES & USES
A12: Total Project Cost | B12: ='1️⃣ Acquisition'!B14 -> 5875000
A13: Less: Loan Amount | B13: =LoanAmount -> 3750000
A14: EQUITY REQUIRED | B14: =B12-B13 -> 2125000
A16: CAPITAL STACK
A17: Loan-to-Value (LTV) % | B17: =IF(PurchasePrice>0,LoanAmount/PurchasePrice,0) -> 0.75
A18: Loan-to-Cost (LTC) % | B18: =IF(B12>0,LoanAmount/B12,0) -> 0.63829787
A19: Equity % | B19: =IF(B12>0,B14/B12,0) -> 0.36170213
A21: YEAR 1 RETURNS
A22: Year 1 NOI | B22: =Year1NOI -> 396550
A23: Less: Annual Debt Service | B23: =B8 -> 287165.41
A24: Year 1 Cash Flow | B24: =B22-B23 -> 109384.59
A26: KEY RETURN METRICS
A27: Going-In Cap Rate % | B27: =IF(PurchasePrice>0,Year1NOI/PurchasePrice,0) -> 0.07931
A28: Cash-on-Cash Return % | B28: =IF(B14>0,B24/B14,0) -> 0.051475102
A29: Debt Service Coverage Ratio | B29: =IF(B23>0,B22/B23,0) -> 1.3809114
A30: Debt Yield % | B30: =IF(LoanAmount>0,B22/LoanAmount,0) -> 0.10574667

Sheet 6️⃣ Exit Analysis
A1: EXIT ANALYSIS & INVESTOR RETURNS
A3: EXIT ASSUMPTIONS
A4: Hold Period (Years) | B4: =HoldPeriod -> 5
A5: Exit Cap Rate % | B5: =ExitCapRate/100 -> 0.055
A6: Exit NOI (Based on Hold Period) | B6: =IF(HoldPeriod<=5,Year5NOI,Year10NOI) -> 450495.9
A8: SALE CALCULATIONS
A9: Gross Sale Price | B9: =IF(ExitCapRate>0,B6/(ExitCapRate/100),0) -> 8190834.5
A10: Less: Selling Costs (2%) | B10: =B9*0.02 -> 163816.69
A11: Net Sale Proceeds | B11: =B9-B10 -> 8027017.8
A13: Less: Remaining Loan Balance | B13: =IF(HoldPeriod>=LoanTerm,0,IF(AND(InterestRate>0,Amortization>0,LoanAmount>0),FV(InterestRate/100,HoldPeriod,-PMT(InterestRate/100,Amortization,LoanAmount),LoanAmount),LoanAmount)) -> -6772841.7
A15: NET PROCEEDS TO EQUITY | B15: =B11-B13 -> 14799860
A17: INVESTOR RETURN SUMMARY
A18: Initial Equity Investment | B18: ='5️⃣ Financing & Returns'!B14 -> 2125000
A19: Total Cash Flow (All Years) | B19: =Year1CashFlow*HoldPeriod -> 546922.96
A20: Net Sale Proceeds | B20: =B15 -> 14799860
A21: TOTAL RETURN TO EQUITY | B21: =B19+B20 -> 15346783
A23: Note: Percentages below show TOTAL return over entire hold period, not annual
A24: RETURN METRICS
A25: Total Return % (Cumulative) | B25: =IF(B18>0,(B21/B18)-1,0) -> 6.2220153
A26: Equity Multiple (Total Return ÷ Initial Investment) | B26: =IF(B18>0,B21/B18,0) -> 7.2220153
A27: Average Annual Return % | B27: =IF(AND(B26>1,HoldPeriod>0),(B26-1)/HoldPeriod,0) -> 1.2444031

Sheet 7️⃣ Summary Dashboard
A1: INVESTMENT SUMMARY DASHBOARD
A3: PROPERTY OVERVIEW
A4: Property Name | B4: =PropName -> 123 Main Street
A5: Location | B5: =City&", "&State&" "&ZipCode -> Austin, TX 78701
A6: Property Type | B6: =PropType -> Multi-Family
A7: Number of Units | B7: =Units -> 24
A8: Total Square Feet | B8: =SqFt -> 18000
A9: Year Built | B9: =YearBuilt -> 2005
A11: INVESTMENT SUMMARY
A12: Total Project Cost | B12: ='1️⃣ Acquisition'!B14 -> 5875000
A13: Purchase Price | B13: =PurchasePrice -> 5000000
A14: Price Per Unit | B14: ='1️⃣ Acquisition'!B17 -> 244791.67
A15: Price Per SF | B15: ='1️⃣ Acquisition'!B18 -> 326.38889
A17: FINANCING
A18: Loan Amount | B18: =LoanAmount -> 3750000
A19: Equity Required | B19: ='5️⃣ Financing & Returns'!B14 -> 2125000
A20: LTV Ratio | B20: ='5️⃣ Financing & Returns'!B17 -> 0.75
A21: Interest Rate | B21: =InterestRate/100 -> 0.065
A22: Loan Term | B22: =LoanTerm -> 10
A24: YEAR 1 PERFORMANCE
A25: Effective Gross Income | B25: =Year1EGI -> 589000
A26: Total Operating Expenses | B26: ='2️⃣ Year 1 Pro Forma'!B25 -> 192450
A27: Net Operating Income | B27: =Year1NOI -> 396550
A28: Annual Debt Service | B28: ='5️⃣ Financing & Returns'!B8 -> 287165.41
A29: Year 1 Cash Flow | B29: =Year1CashFlow -> 109384.59
A31: KEY RETURN METRICS
A32: Going-In Cap Rate | B32: ='5️⃣ Financing & Returns'!B27 -> 0.07931
A33: Cash-on-Cash Return | B33: ='5️⃣ Financing & Returns'!B28 -> 0.051475102
A34: DSCR | B34: ='5️⃣ Financing & Returns'!B29 -> 1.3809114
A35: OpEx Ratio | B35: ='2️⃣ Year 1 Pro Forma'!B30 -> 0.32674024
A37: EXIT ANALYSIS
A38: Hold Period | B38: =HoldPeriod -> 5
A39: Exit Cap Rate | B39: =ExitCapRate/100 -> 0.055
A40: Projected Sale Price | B40: ='6️⃣ Exit Analysis'!B9 -> 8190834.5
A41: Total Return to Equity | B41: ='6️⃣ Exit Analysis'!B21 -> 15346783
A42: Equity Multiple | B42: ='6️⃣ Exit Analysis'!B26 -> 7.2220153
A43: Avg Annual Return | B43: ='6️⃣ Exit Analysis'!B27 -> 1.2444031
