Workbook

Sheet INSTRUCTIONS
A1: CAPSERIESX RISK ASSESSMENT TEMPLATE
A2: Comprehensive Investment Risk Analysis Framework
A4: Version: 1.0 | Last Updated: December 2024 | © DeFi Assets LLC
A6: PURPOSE & OVERVIEW
A8: This template helps you systematically identify, quantify, and develop mitigation strategies for ALL investment risks.
A9: A thorough risk assessment is REQUIRED for Gold and Platinum partners and demonstrates investment sophistication.
A11: WHAT THIS TEMPLATE INCLUDES:
A12: • Risk Identification Matrix - Systematic review of all risk categories
A13: • Top 5 Risks Analysis - Detailed assessment of highest-priority risks
A14: • Probability & Impact Scoring - Quantify each risk's likelihood and financial impact
A15: • Mitigation Strategy Builder - Document how you'll address each risk
A16: • Reserve Fund Calculator - Determine appropriate capital reserves
... A78: Need help quantifying risks? Review your Market Research and Financial Analysis

Sheet SUMMARY
A1: RISK ASSESSMENT - EXECUTIVE SUMMARY
A3: Property Address: | B3: =Top_5_Risks!B3
A4: Analysis Date:
A5: Partner Name:
A7: OVERALL RISK RATING
A8: Investment Risk Profile:
A10: TOP 5 RISKS SUMMARY
A11: # | B11: Risk Description | C11: Category | D11: Probability | E11: Impact | F11: Risk Score
A12: 1 | B12: =Top_5_Risks!B7 | C12: =Top_5_Risks!B8 | D12: =Top_5_Risks!B9 | E12: =Top_5_Risks!D9 | F12: =Top_5_Risks!B10
A13: 2 | B13: =Top_5_Risks!B17 | C13: =Top_5_Risks!B18 | D13: =Top_5_Risks!B19 | E13: =Top_5_Risks!D19 | F13: =Top_5_Risks!B20
A14: 3 | B14: =Top_5_Risks!B27 | C14: =Top_5_Risks!B28 | D14: =Top_5_Risks!B29 | E14: =Top_5_Risks!D29 | F14: =Top_5_Risks!B30
A15: 4 | B15: =Top_5_Risks!B37 | C15: =Top_5_Risks!B38 | D15: =Top_5_Risks!B39 | E15: =Top_5_Risks!D39 | F15: =Top_5_Risks!B40
A16: 5 | B16: =Top_5_Risks!B47 | C16: =Top_5_Risks!B48 | D16: =Top_5_Risks!B49 | E16: =Top_5_Risks!D49 | F16: =Top_5_Risks!B50
A18: RESERVE FUND REQUIREMENTS
A19: Operating Reserve: | B19: =Reserve_Funds!B10
A20: CapEx Reserve: | B20: =Reserve_Funds!E30
A21: Other Contingency: | B21: =SUM(Reserve_Funds!B42:B46)
A23: TOTAL RESERVES REQUIRED: | B23: =SUM(B20:B22)
A25: RISK MITIGATION STATUS
A26: Total Mitigation Cost:
A27: Mitigation Timeline:
A28: Responsible Parties:
A30: INVESTMENT DECISION FRAMEWORK
A31: Are all material risks identified and mitigated?
A32: Are reserve funds adequate?
A33: Overall Risk vs. Return Assessment:
A35: PROCEED WITH INVESTMENT?
A36: Supporting Rationale:
A39: Additional Notes / Concerns:

Sheet Risk_Categories
A1: INVESTMENT RISK IDENTIFICATION CHECKLIST
A2: Check all risks that apply to your investment. This helps ensure you don't miss important risks.
A4: 1. MARKET RISKS
A5: Risk | B5: Applies? | C5: Level | D5: Priority | E5: Notes
A6: Rental rate decline
A7: Increased vacancy rates
A8: Market oversupply (new construction)
A9: Economic recession / job losses
A10: Population decline / out-migration
A11: Neighborhood deterioration
A12: Competing properties offering concessions
A13: Changing tenant demographics
A15: 2. FINANCIAL RISKS
A16: Risk | B16: Applies? | C16: Level | D16: Priority | E16: Notes
A17: Interest rate increases
A18: Difficulty refinancing at maturity
A19: Operating cost increases (taxes, insurance, utilities)
A20: Revenue shortfall vs projections
A21: Construction cost overruns
A22: CapEx needs exceed reserves
A23: Difficulty raising additional capital if needed
A24: Cash flow insufficient for debt service
A26: 3. OPERATIONAL RISKS
A27: Risk | B27: Applies? | C27: Level | D27: Priority | E27: Notes
A28: Property management performance issues
A29: Key personnel turnover
A30: Deferred maintenance worse than expected
A31: Major system failure (HVAC, roof, etc.)
A32: Tenant disputes / evictions
A33: Extended turnover time between tenants
A34: Higher-than-expected maintenance costs
A35: Vendor performance issues
A37: 4. LEGAL & REGULATORY RISKS
A38: Risk | B38: Applies? | C38: Level | D38: Priority | E38: Notes
A39: Zoning changes / restrictions
A40: Rent control implementation
A41: Property tax reassessment / increases
A42: Code violations / compliance issues
A43: Title defects / easement issues
A44: Tenant lawsuits
...

Sheet Top_5_Risks
A1: TOP 5 INVESTMENT RISKS - DETAILED ANALYSIS
A2: Complete detailed analysis for your TOP 5 highest-priority risks. Rank from #1 (highest) to #5.
A3: Property Address:
A5: RISK #1
A6: Risk Description:
A7: Risk Category:
A8: Probability: | C8: Impact Level: | E8: Financial Impact:
A9: Risk Score: | B9: =IF(D8="Critical",4,IF(D8="High",3,IF(D8="Medium",2,1)))*B8/100 | C9: (Scale: 0-4, auto-calculated)
A10: Supporting Data/Evidence:
A11: Mitigation Strategy:
A12: Cost to Mitigate: | C12: Timeline: | E12: Responsible Party:
A13: Residual Risk After Mitigation:
A15: RISK #2
A16: Risk Description:
A17: Risk Category:
A18: Probability: | C18: Impact Level: | E18: Financial Impact:
A19: Risk Score: | B19: =IF(D18="Critical",4,IF(D18="High",3,IF(D18="Medium",2,1)))*B18/100 | C19: (Scale: 0-4, auto-calculated)
A20: Supporting Data/Evidence:
A21: Mitigation Strategy:
A22: Cost to Mitigate: | C22: Timeline: | E22: Responsible Party:
A23: Residual Risk After Mitigation:
A25: RISK #3
A26: Risk Description:
A27: Risk Category:
A28: Probability: | C28: Impact Level: | E28: Financial Impact:
A29: Risk Score: | B29: =IF(D28="Critical",4,IF(D28="High",3,IF(D28="Medium",2,1)))*B28/100 | C29: (Scale: 0-4, auto-calculated)
A30: Supporting Data/Evidence:
A31: Mitigation Strategy:
A32: Cost to Mitigate: | C32: Timeline: | E32: Responsible Party:
A33: Residual Risk After Mitigation:
A35: RISK #4
A36: Risk Description:
A37: Risk Category:
A38: Probability: | C38: Impact Level: | E38: Financial Impact:
A39: Risk Score: | B39: =IF(D38="Critical",4,IF(D38="High",3,IF(D38="Medium",2,1)))*B38/100 | C39: (Scale: 0-4, auto-calculated)
A40: Supporting Data/Evidence:
A41: Mitigation Strategy:
A42: Cost to Mitigate: | C42: Timeline: | E42: Responsible Party:
A43: Residual Risk After Mitigation:
A45: RISK #5
...

Sheet Reserve_Funds
A1: RESERVE FUND ANALYSIS & CALCULATOR
A2: Calculate required reserve funds to protect against identified risks. Minimum 6 months operating expenses recommended.
A4: A. OPERATING EXPENSE RESERVE
A5: Annual Operating Expenses:
A6: Monthly Operating Expenses: | B6: =B5/12
A8: Recommended Reserve (months):
A9: Operating Reserve Required: | B9: =B6*B9
A11: B. CAPITAL EXPENDITURE RESERVE
A12: CapEx Category | B12: Est. Cost | C12: Probability | D12: Year Expected | E12: Reserve Needed
A13: Roof Replacement | E13: =B13*C13/100
A14: HVAC System | E14: =B14*C14/100
A15: Parking Lot Repaving | E15: =B15*C15/100
A16: Exterior Paint/Siding | E16: =B16*C16/100
A17: Plumbing/Pipes | E17: =B17*C17/100
A18: Windows/Doors | E18: =B18*C18/100
A19: Landscaping | E19: =B19*C19/100
A20: Other Major Items | E20: =B20*C20/100
A21: TOTAL CapEx Reserve Required: | E21: =SUM(E13:E20)
A23: C. OTHER CONTINGENCY RESERVES
A24: Lease-Up Reserve (if needed):
A25: TI/Concessions Reserve:
A26: Legal/Unexpected Reserve:
A27: Environmental Remediation:
A28: Other Contingencies:
A30: TOTAL RESERVE FUND SUMMARY
A31: Operating Reserve: | B31: =B10
A32: CapEx Reserve: | B32: =E21
A33: Other Contingency Reserves: | B33: =SUM(B24:B28)
A35: TOTAL RESERVES REQUIRED: | B35: =B31+B32+B33
